Workbook

Sheet Exerzitien_archive_de
E2: 2024_advent | F2: 2023_advent | G2: 2023_lent | H2: 2023_fs
B3: ='exerzitien-katalog'!I2 -> Fastenzeit 2026 mit dem heiligen Johannes vom Kreuz | C3: {=INDEX('exerzitien-katalog'!$I:$I,COLUMN(C3)+1)} -> Fastenzeit 2025 mit Thérèse von Lisieux und das Östergeheimnis | D3: {=INDEX('exerzitien-katalog'!$I:$I,COLUMN(D3)+1)} -> Advent 2024 mit der Hl. Thérèse vom Kind Jesu | E3: {=INDEX('exerzitien-katalog'!$I:$I,COLUMN(E3)+1)} -> Fastenzeit 2024 mit Pater Jacuqes von Jesus (1900-1945) | F3: {=INDEX('exerzitien-katalog'!$I:$I,COLUMN(F3)+1)} -> Advent 2023 mit der heiligen Teresa de Los Andes (1900-1920) | G3: {=INDEX('exerzitien-katalog'!$I:$I,COLUMN(G3)+1)} -> Fastenzeit 2023: Das Gebet | H3: {=INDEX('exerzitien-katalog'!$I:$I,COLUMN(H3)+1)} -> Advent 2022 in der Schule der Heiligen des Karmel | I3: {=INDEX('exerzitien-katalog'!$I:$I,COLUMN(I3)+1)} -> Fastenzeit 2022: Gottes Barmherzigkeit leben mit den Heiligen des Karmel | J3: {=INDEX('exerzitien-katalog'!$I:$I,COLUMN(J3)+1)} -> Advent 2021 mit der hl. Thérèse von Lisieux und Maria Montessori | ... AE3: {=INDEX('exerzitien-katalog'!$I:$I,COLUMN(AE3)+1)} -> 0
B4: ='exerzitien-katalog'!J2 -> Christus in der Tiefe des Herzens begegnen | C4: {=INDEX('exerzitien-katalog'!$J:$J,COLUMN(C4)+1)} -> „Aus Liebe sterben, das ist meine Hoffnung“ | D4: {=INDEX('exerzitien-katalog'!$J:$J,COLUMN(D4)+1)} -> „Kind sein vor Gott“ | E4: {=INDEX('exerzitien-katalog'!$J:$J,COLUMN(E4)+1)} -> Durch das Kreuz zum Licht | F4: {=INDEX('exerzitien-katalog'!$J:$J,COLUMN(F4)+1)} -> Leben in der Göttlichen Freude | G4: {=INDEX('exerzitien-katalog'!$J:$J,COLUMN(G4)+1)} -> Das Gebet - ein Weg, unsere Berufung als Kind Gottes zu leben | H4: {=INDEX('exerzitien-katalog'!$J:$J,COLUMN(H4)+1)} -> Die Gegenwart Gottes in unserem Leben erfahren | I4: {=INDEX('exerzitien-katalog'!$J:$J,COLUMN(I4)+1)} -> Die Barmherzigkeit Gottes leben | J4: {=INDEX('exerzitien-katalog'!$J:$J,COLUMN(J4)+1)} -> "Die Kindschaft der Seele" Unser Morgenrot Wecken | ... AE4: {=INDEX('exerzitien-katalog'!$J:$J,COLUMN(AE4)+1)} -> 0
B5: ='exerzitien-katalog'!K2 -> Wir bieten Ihnen Online-Exerzitien in der Schule des heiligen Johannes vom Kreuz an. In diesen Exerzitien werden wir im Lichte der Evangelien unsere Beziehung zu Jesus vertiefen, um im Heiligen Geist wieder zur Vertrautheit mit Ihm und mit Gott Vater in der Tiefe unseres Herzens zu gelangen. Es wird ein Weg der inneren Befreiung sein, auf dem uns Johannes vom Kreuz zuverlässig und sicher führen wird. Er wird uns in einer zunehmend auf das Äußere hin orientierten Welt lehren, wieder in unser tiefstes Inneres einzugehen, wo Christus, der Bräutigam der Kirche, uns begegnen und reinigen will, damit wir mit Ihm im Feuer des Heiligen Geistes zu den innig geliebten Kindern des Vaters werden. | C5: {=INDEX('exerzitien-katalog'!$K:$K,COLUMN(C5)+1)} -> Die heilige Thérèse von Lisieux wird uns in sechs Schritten zur Osterfreude führen: - 1. Sonntag: „Selig jener, der würdig erachtet wurde, Anfechtung zu erleiden!“ - 2. Sonntag: „O [Heiliges] Antlitz, schöner als die Lilien und Rosen im Frühling!“ - 3. Sonntag: „Ich fühlte ein großes Verlangen, für die Bekehrung der Sünder zu arbeiten“ - 4. Sonntag: „Hätte ich auch alle begehbaren Sünden auf dem Gewissen ...“ - 5. Sonntag: „Eine arme Sünderin wie ich“ - Karwoche: „Schau Jesus ins Antlitz ... Da wirst du sehen, wie er uns liebt!“ - Ostern: „Dies ist mein Himmel ... dies ist meine Bestimmung: Leben aus Liebe!!!...“ Jeden Freitag erhalten Sie eine E-Mail-Nachricht: Dort können Sie den Text herunterladen (in drei Formaten: PDF, Word, PDF im Handyformat) oder die Audio-Version als Podcast anhören. Der Inhalt der Betrachtung wird vom Sonntagsevangelium ausgehen und uns in die Schule der heiligen Thérèse von Lisieux führen. Ein Fastenkalender (Zitate und Bilder) wird Sie außerdem jeden Tag, von Montag bis Samstag, durch geistliche Impulse inspirieren. | D5: {=INDEX('exerzitien-katalog'!$K:$K,COLUMN(D5)+1)} -> Diese Online-Exerzitien wollen in den Geist und das Gebet der Jüngsten unter allen Kirchenlehrern einführen, deren Geburtstag sich letztes Jahr zum 150. Mal jährte: die hl. Thérèse vom Kinde Jesus (von Lisieux). Wir werden dies tun, indem wir uns in erster Linie auf die Schriften der Heiligen stützen, die uns ein umfangreiches schriftliches Werk hinterlassen hat. Doch diese erklären nicht alles. Thérèses fulminante Berufung kann nur vor dem Hintergrund des unergründlichen Geheimnisses, von dem ihr ganzes Leben Zeugnis ablegt, vollständig verstanden werden: dem der göttlichen Barmherzigkeit. | E5: {=INDEX('exerzitien-katalog'!$K:$K,COLUMN(E5)+1)} -> „Durch das Kreuz zum Licht“: So lautet der Anfang der Worte, die Pater Jacques von Jesus im März 1945 im Konzentrationslager Gusen (Österreich) mit Bleistift in ein Notizbuch kritzelte. Sie haben den Wert eines geistlichen Testaments. Dieser bemerkenswerte Erzieher, der im Januar 1944 im Karmeliterkloster von Avon von der Gestapo verhaftet worden war (ein Vorfall, der in dem Film „Auf Wiedersehen, Kinder“ von Louis Malle aufgegriffen wird) und dessen Seligsprechungsprozess im Gange ist, wird uns einen wirkkräftigen Fastenweg aufzeigen, um dem Licht Christi entgegenzugehen. | F5: {=INDEX('exerzitien-katalog'!$K:$K,COLUMN(F5)+1)} -> „Gott ist unendliche Freude." Dieser berühmte Ausspruch der heiligen Teresa de Los Andes (1900-1920), der ersten Chilenin, die heiliggesprochen wurde, ist das Leitmotiv für diese Exerzitien im Advent 2023: Ja, Gott ist sehr viel liebenswürdiger, schöner und liebevoller als wir im Allgemeinen denken! Teresa wird uns dies erkennen lassen, indem sie uns das Beispiel einer liebenswürdigen Heiligkeit vor Augen führt und uns leicht verständliche Ratschläge gibt, damit auch wir unser Leben in der göttlichen Freude verankern können. In ihrer Schule werden wir erkennen, dass wir – an der Seite des göttlichen Neugeborenen – zu einer frohen Heiligkeit gelangen können … | G5: {=INDEX('exerzitien-katalog'!$K:$K,COLUMN(G5)+1)} -> „Kinder Gottes: Wir sind es bereits im Keim durch unsere Taufe. Aber wie können wir unsere tiefe Berufung, für Gott Söhne und Töchter zu werden, voll und ganz verwirklichen? Das Gebet, das persönliche Gebet ist ein bevorzugter Weg für diese Neuschöpfung in Christus. Diese Exerzitien in der Fastenzeit werden uns helfen, unser geistliches Leben tiefgreifend zu erneuern, damit wir uns an der Ostergnade in kindlicher Dankbarkeit erfreuen können!" | H5: {=INDEX('exerzitien-katalog'!$K:$K,COLUMN(H5)+1)} -> Das Weihnachtsgeheimnis ist das Geheimnis Gottes, der sich in unserem Menschsein zu unserer Erlösung gegenwärtig macht. Vor 2000 Jahren in der Krippe von Bethlehem anwesend, ist Christus Jesus hier und jetzt, mitten unter uns und in jedem von uns gegenwärtig. Während dieser Einkehrtage im Advent werden wir uns in die Schule der Heiligen des Karmel begeben, um diese Gegenwart Gottes in unserem Leben auf erneuerte Weise zu empfangen. Gehen wir "auf dieser wunderbaren Straße der Gegenwart Gottes"! | I5: {=INDEX('exerzitien-katalog'!$K:$K,COLUMN(I5)+1)} -> 0 | J5: {=INDEX('exerzitien-katalog'!$K:$K,COLUMN(J5)+1)} -> Die heilige Thérèse vom Kinde Jesus (1873-1897) und Maria Montessori (1870-1952) sind beide Doktoren. Die eine führt die Kirche zur Kindschaft, die andere das Kind zur Kirche. Als Frauen und Prophetinnen haben sie aus der Quelle desselben Evangeliums geschöpft. Durch ihre Stimmen, die im Wechsel gleichsam als Echo widerhallen, lüftet Gott den geheimnisvollen Schleier seines Antlitzes, das den Kleinen zugetan ist. | ... AE5: {=INDEX('exerzitien-katalog'!$K:$K,COLUMN(AE5)+1)} -> 0
B6: ='exerzitien-katalog'!L2 -> img/FS26_header_DE.png | C6: {=INDEX('exerzitien-katalog'!$L:$L,COLUMN(C6)+1)} -> img/FS25_header_DE.png | D6: {=INDEX('exerzitien-katalog'!$L:$L,COLUMN(D6)+1)} -> img/AD24_header_DE.png | E6: {=INDEX('exerzitien-katalog'!$L:$L,COLUMN(E6)+1)} -> img/FS24_header_DE.png | F6: {=INDEX('exerzitien-katalog'!$L:$L,COLUMN(F6)+1)} -> img/AD23_header_DE.png | G6: {=INDEX('exerzitien-katalog'!$L:$L,COLUMN(G6)+1)} -> img/FS23_header_DE.png | H6: {=INDEX('exerzitien-katalog'!$L:$L,COLUMN(H6)+1)} -> img/AD22_header_DE.png | I6: {=INDEX('exerzitien-katalog'!$L:$L,COLUMN(I6)+1)} -> img/FS22_header_DE.png | J6: {=INDEX('exerzitien-katalog'!$L:$L,COLUMN(J6)+1)} -> img/AD21_header_DE.png | ... AE6: {=INDEX('exerzitien-katalog'!$L:$L,COLUMN(AE6)+1)} -> 0
C7: {=INDEX('exerzitien-katalog'!$A:$A,COLUMN(C7)+1)} -> lent-2025-therese-von-lisieux | D7: {=INDEX('exerzitien-katalog'!$A:$A,COLUMN(D7)+1)} -> advent-2024-therese-von-lisieux | E7: {=INDEX('exerzitien-katalog'!$A:$A,COLUMN(E7)+1)} -> lent-2024-pater-jacques-de-jesus | F7: {=INDEX('exerzitien-katalog'!$A:$A,COLUMN(F7)+1)} -> advent-2023-therese-des-andes | G7: {=INDEX('exerzitien-katalog'!$A:$A,COLUMN(G7)+1)} -> lent-2023-oraison-weg-der-kindlichen-berufung | H7: {=INDEX('exerzitien-katalog'!$A:$A,COLUMN(H7)+1)} -> advent-2022-gott-in-unserem-leben | I7: {=INDEX('exerzitien-katalog'!$A:$A,COLUMN(I7)+1)} -> lent-2022-barmherzigkeit-gottes-mit-den-heiligen-des-karmels | J7: {=INDEX('exerzitien-katalog'!$A:$A,COLUMN(J7)+1)} -> advent-2021-kindheit-der-seele | ... AE7: {=INDEX('exerzitien-katalog'!$A:$A,COLUMN(AE7)+1)} -> 0
C8: {=INDEX('exerzitien-katalog'!$F:$F,COLUMN(C8)+1)} -> 2025-03-05 | D8: {=INDEX('exerzitien-katalog'!$F:$F,COLUMN(D8)+1)} -> 2024-11-27 | E8: {=INDEX('exerzitien-katalog'!$F:$F,COLUMN(E8)+1)} -> 2024-02-14 | F8: {=INDEX('exerzitien-katalog'!$F:$F,COLUMN(F8)+1)} -> 2023-11-29 | G8: {=INDEX('exerzitien-katalog'!$F:$F,COLUMN(G8)+1)} -> 2023-02-22 | H8: {=INDEX('exerzitien-katalog'!$F:$F,COLUMN(H8)+1)} -> 2022-11-23 | I8: {=INDEX('exerzitien-katalog'!$F:$F,COLUMN(I8)+1)} -> 2022-03-02 | J8: {=INDEX('exerzitien-katalog'!$F:$F,COLUMN(J8)+1)} -> 2021-11-26 | ... AE8: {=INDEX('exerzitien-katalog'!$F:$F,COLUMN(AE8)+1)} -> 0
C9: {=INDEX('exerzitien-katalog'!$G:$G,COLUMN(C9)+1)} -> 2025-04-27 | D9: {=INDEX('exerzitien-katalog'!$G:$G,COLUMN(D9)+1)} -> 2025-01-05 | E9: {=INDEX('exerzitien-katalog'!$G:$G,COLUMN(E9)+1)} -> 2024-04-07 | F9: {=INDEX('exerzitien-katalog'!$G:$G,COLUMN(F9)+1)} -> 2023-12-25 | G9: {=INDEX('exerzitien-katalog'!$G:$G,COLUMN(G9)+1)} -> 2023-04-16 | H9: {=INDEX('exerzitien-katalog'!$G:$G,COLUMN(H9)+1)} -> 2023-01-01 | I9: {=INDEX('exerzitien-katalog'!$G:$G,COLUMN(I9)+1)} -> 2022-04-24 | J9: {=INDEX('exerzitien-katalog'!$G:$G,COLUMN(J9)+1)} -> 2022-01-02 | ... AE9: {=INDEX('exerzitien-katalog'!$G:$G,COLUMN(AE9)+1)} -> 0
B10: <!doctype html> | C10: <!doctype html> | D10: <!doctype html> | E10: <!doctype html> | F10: <!doctype html> | G10: <!doctype html> | H10: <!doctype html> | I10: <!doctype html> | J10: <!doctype html> | K10: <!doctype html> | L10: <!doctype html> | M10: <!doctype html> | N10: <!doctype html> | O10: <!doctype html> | P10: <!doctype html> | Q10: <!doctype html> | R10: <!doctype html> | S10: <!doctype html> | T10: <!doctype html> | U10: <!doctype html> | V10: <!doctype html> | W10: <!doctype html> | X10: <!doctype html> | Y10: <!doctype html> | Z10: <!doctype html> | AA10: <!doctype html> | AB10: <!doctype html> | AC10: <!doctype html> | AD10: <!doctype html> | AE10: <!doctype html> | AF10: <!doctype html> | AG10: <!doctype html>
B11: <html lang="de"> | C11: <html lang="de"> | D11: <html lang="de"> | E11: <html lang="de"> | F11: <html lang="de"> | G11: <html lang="de"> | H11: <html lang="de"> | I11: <html lang="de"> | J11: <html lang="de"> | K11: <html lang="de"> | L11: <html lang="de"> | M11: <html lang="de"> | N11: <html lang="de"> | O11: <html lang="de"> | P11: <html lang="de"> | Q11: <html lang="de"> | R11: <html lang="de"> | S11: <html lang="de"> | T11: <html lang="de"> | U11: <html lang="de"> | V11: <html lang="de"> | W11: <html lang="de"> | X11: <html lang="de"> | Y11: <html lang="de"> | Z11: <html lang="de"> | AA11: <html lang="de"> | AB11: <html lang="de"> | AC11: <html lang="de"> | AD11: <html lang="de"> | AE11: <html lang="de"> | AF11: <html lang="de"> | AG11: <html lang="de">
B12: <head> | C12: <head> | D12: <head> | E12: <head> | F12: <head> | G12: <head> | H12: <head> | I12: <head> | J12: <head> | K12: <head> | L12: <head> | M12: <head> | N12: <head> | O12: <head> | P12: <head> | Q12: <head> | R12: <head> | S12: <head> | T12: <head> | U12: <head> | V12: <head> | W12: <head> | X12: <head> | Y12: <head> | Z12: <head> | AA12: <head> | AB12: <head> | AC12: <head> | AD12: <head> | AE12: <head> | AF12: <head> | AG12: <head>
B13: <meta charset="UTF-8" /> | C13: <meta charset="UTF-8" /> | D13: <meta charset="UTF-8" /> | E13: <meta charset="UTF-8" /> | F13: <meta charset="UTF-8" /> | G13: <meta charset="UTF-8" /> | H13: <meta charset="UTF-8" /> | I13: <meta charset="UTF-8" /> | J13: <meta charset="UTF-8" /> | K13: <meta charset="UTF-8" /> | L13: <meta charset="UTF-8" /> | M13: <meta charset="UTF-8" /> | N13: <meta charset="UTF-8" /> | O13: <meta charset="UTF-8" /> | P13: <meta charset="UTF-8" /> | Q13: <meta charset="UTF-8" /> | R13: <meta charset="UTF-8" /> | S13: <meta charset="UTF-8" /> | T13: <meta charset="UTF-8" /> | U13: <meta charset="UTF-8" /> | V13: <meta charset="UTF-8" /> | W13: <meta charset="UTF-8" /> | X13: <meta charset="UTF-8" /> | Y13: <meta charset="UTF-8" /> | Z13: <meta charset="UTF-8" /> | AA13: <meta charset="UTF-8" /> | AB13: <meta charset="UTF-8" /> | AC13: <meta charset="UTF-8" /> | AD13: <meta charset="UTF-8" /> | AE13: <meta charset="UTF-8" /> | AF13: <meta charset="UTF-8" /> | AG13: <meta charset="UTF-8" />
B14: <meta name="viewport" content="width=device-width, initial-scale=1.0" /> | C14: <meta name="viewport" content="width=device-width, initial-scale=1.0" /> | D14: <meta name="viewport" content="width=device-width, initial-scale=1.0" /> | E14: <meta name="viewport" content="width=device-width, initial-scale=1.0" /> | F14: <meta name="viewport" content="width=device-width, initial-scale=1.0" /> | G14: <meta name="viewport" content="width=device-width, initial-scale=1.0" /> | H14: <meta name="viewport" content="width=device-width, initial-scale=1.0" /> | I14: <meta name="viewport" content="width=device-width, initial-scale=1.0" /> | J14: <meta name="viewport" content="width=device-width, initial-scale=1.0" /> | K14: <meta name="viewport" content="width=device-width, initial-scale=1.0" /> | L14: <meta name="viewport" content="width=device-width, initial-scale=1.0" /> | M14: <meta name="viewport" content="width=device-width, initial-scale=1.0" /> | N14: <meta name="viewport" content="width=device-width, initial-scale=1.0" /> | O14: <meta name="viewport" content="width=device-width, initial-scale=1.0" /> | P14: <meta name="viewport" content="width=device-width, initial-scale=1.0" /> | Q14: <meta name="viewport" content="width=device-width, initial-scale=1.0" /> | R14: <meta name="viewport" content="width=device-width, initial-scale=1.0" /> | S14: <meta name="viewport" content="width=device-width, initial-scale=1.0" /> | T14: <meta name="viewport" content="width=device-width, initial-scale=1.0" /> | U14: <meta name="viewport" content="width=device-width, initial-scale=1.0" /> | V14: <meta name="viewport" content="width=device-width, initial-scale=1.0" /> | W14: <meta name="viewport" content="width=device-width, initial-scale=1.0" /> | X14: <meta name="viewport" content="width=device-width, initial-scale=1.0" /> | Y14: <meta name="viewport" content="width=device-width, initial-scale=1.0" /> | Z14: <meta name="viewport" content="width=device-width, initial-scale=1.0" /> | AA14: <meta name="viewport" content="width=device-width, initial-scale=1.0" /> | AB14: <meta name="viewport" content="width=device-width, initial-scale=1.0" /> | AC14: <meta name="viewport" content="width=device-width, initial-scale=1.0" /> | AD14: <meta name="viewport" content="width=device-width, initial-scale=1.0" /> | AE14: <meta name="viewport" content="width=device-width, initial-scale=1.0" /> | AF14: <meta name="viewport" content="width=device-width, initial-scale=1.0" /> | AG14: <meta name="viewport" content="width=device-width, initial-scale=1.0" />
B15: <title>Fastenzeit 2026 mit Johannes vom Kreuz</title> | C15: ="<title>"&C3&"</title>" -> <title>Fastenzeit 2025 mit Thérèse von Lisieux und das Östergeheimnis</title> | D15: ="<title>"&D3&"</title>" -> <title>Advent 2024 mit der Hl. Thérèse vom Kind Jesu</title> | E15: ="<title>"&E3&"</title>" -> <title>Fastenzeit 2024 mit Pater Jacuqes von Jesus (1900-1945)</title> | F15: ="<title>"&F3&"</title>" -> <title>Advent 2023 mit der heiligen Teresa de Los Andes (1900-1920)</title> | G15: ="<title>"&G3&"</title>" -> <title>Fastenzeit 2023: Das Gebet</title> | H15: ="<title>"&H3&"</title>" -> <title>Advent 2022 in der Schule der Heiligen des Karmel</title> | I15: ="<title>"&I3&"</title>" -> <title>Fastenzeit 2022: Gottes Barmherzigkeit leben mit den Heiligen des Karmel</title> | J15: ="<title>"&J3&"</title>" -> <title>Advent 2021 mit der hl. Thérèse von Lisieux und Maria Montessori</title> | ... AG15: ="<title>"&AG3&"</title>" -> <title></title>
B17: <link rel="preconnect" href="https://fonts.googleapis.com" /> | C17: <link rel="preconnect" href="https://fonts.googleapis.com" /> | D17: <link rel="preconnect" href="https://fonts.googleapis.com" /> | E17: <link rel="preconnect" href="https://fonts.googleapis.com" /> | F17: <link rel="preconnect" href="https://fonts.googleapis.com" /> | G17: <link rel="preconnect" href="https://fonts.googleapis.com" /> | H17: <link rel="preconnect" href="https://fonts.googleapis.com" /> | I17: <link rel="preconnect" href="https://fonts.googleapis.com" /> | J17: <link rel="preconnect" href="https://fonts.googleapis.com" /> | K17: <link rel="preconnect" href="https://fonts.googleapis.com" /> | L17: <link rel="preconnect" href="https://fonts.googleapis.com" /> | M17: <link rel="preconnect" href="https://fonts.googleapis.com" /> | N17: <link rel="preconnect" href="https://fonts.googleapis.com" /> | O17: <link rel="preconnect" href="https://fonts.googleapis.com" /> | P17: <link rel="preconnect" href="https://fonts.googleapis.com" /> | Q17: <link rel="preconnect" href="https://fonts.googleapis.com" /> | R17: <link rel="preconnect" href="https://fonts.googleapis.com" /> | S17: <link rel="preconnect" href="https://fonts.googleapis.com" /> | T17: <link rel="preconnect" href="https://fonts.googleapis.com" /> | U17: <link rel="preconnect" href="https://fonts.googleapis.com" /> | V17: <link rel="preconnect" href="https://fonts.googleapis.com" /> | W17: <link rel="preconnect" href="https://fonts.googleapis.com" /> | X17: <link rel="preconnect" href="https://fonts.googleapis.com" /> | Y17: <link rel="preconnect" href="https://fonts.googleapis.com" /> | Z17: <link rel="preconnect" href="https://fonts.googleapis.com" /> | AA17: <link rel="preconnect" href="https://fonts.googleapis.com" /> | AB17: <link rel="preconnect" href="https://fonts.googleapis.com" /> | AC17: <link rel="preconnect" href="https://fonts.googleapis.com" /> | AD17: <link rel="preconnect" href="https://fonts.googleapis.com" /> | AE17: <link rel="preconnect" href="https://fonts.googleapis.com" /> | AF17: <link rel="preconnect" href="https://fonts.googleapis.com" /> | AG17: <link rel="preconnect" href="https://fonts.googleapis.com" />
B18: <link rel="preconnect" href="https://fonts.gstatic.com" crossorigin /> | C18: <link rel="preconnect" href="https://fonts.gstatic.com" crossorigin /> | D18: <link rel="preconnect" href="https://fonts.gstatic.com" crossorigin /> | E18: <link rel="preconnect" href="https://fonts.gstatic.com" crossorigin /> | F18: <link rel="preconnect" href="https://fonts.gstatic.com" crossorigin /> | G18: <link rel="preconnect" href="https://fonts.gstatic.com" crossorigin /> | H18: <link rel="preconnect" href="https://fonts.gstatic.com" crossorigin /> | I18: <link rel="preconnect" href="https://fonts.gstatic.com" crossorigin /> | J18: <link rel="preconnect" href="https://fonts.gstatic.com" crossorigin /> | K18: <link rel="preconnect" href="https://fonts.gstatic.com" crossorigin /> | L18: <link rel="preconnect" href="https://fonts.gstatic.com" crossorigin /> | M18: <link rel="preconnect" href="https://fonts.gstatic.com" crossorigin /> | N18: <link rel="preconnect" href="https://fonts.gstatic.com" crossorigin /> | O18: <link rel="preconnect" href="https://fonts.gstatic.com" crossorigin /> | P18: <link rel="preconnect" href="https://fonts.gstatic.com" crossorigin /> | Q18: <link rel="preconnect" href="https://fonts.gstatic.com" crossorigin /> | R18: <link rel="preconnect" href="https://fonts.gstatic.com" crossorigin /> | S18: <link rel="preconnect" href="https://fonts.gstatic.com" crossorigin /> | T18: <link rel="preconnect" href="https://fonts.gstatic.com" crossorigin /> | U18: <link rel="preconnect" href="https://fonts.gstatic.com" crossorigin /> | V18: <link rel="preconnect" href="https://fonts.gstatic.com" crossorigin /> | W18: <link rel="preconnect" href="https://fonts.gstatic.com" crossorigin /> | X18: <link rel="preconnect" href="https://fonts.gstatic.com" crossorigin /> | Y18: <link rel="preconnect" href="https://fonts.gstatic.com" crossorigin /> | Z18: <link rel="preconnect" href="https://fonts.gstatic.com" crossorigin /> | AA18: <link rel="preconnect" href="https://fonts.gstatic.com" crossorigin /> | AB18: <link rel="preconnect" href="https://fonts.gstatic.com" crossorigin /> | AC18: <link rel="preconnect" href="https://fonts.gstatic.com" crossorigin /> | AD18: <link rel="preconnect" href="https://fonts.gstatic.com" crossorigin /> | AE18: <link rel="preconnect" href="https://fonts.gstatic.com" crossorigin /> | AF18: <link rel="preconnect" href="https://fonts.gstatic.com" crossorigin /> | AG18: <link rel="preconnect" href="https://fonts.gstatic.com" crossorigin />
B19: <link | C19: <link | D19: <link | E19: <link | F19: <link | G19: <link | H19: <link | I19: <link | J19: <link | K19: <link | L19: <link | M19: <link | N19: <link | O19: <link | P19: <link | Q19: <link | R19: <link | S19: <link | T19: <link | U19: <link | V19: <link | W19: <link | X19: <link | Y19: <link | Z19: <link | AA19: <link | AB19: <link | AC19: <link | AD19: <link | AE19: <link | AF19: <link | AG19: <link
B20: href="https://fonts.googleapis.com/css2?family=Cormorant+Garamond:wght@500;600;700&family=Inter:wght@400;500;600;700&display=swap" | C20: href="https://fonts.googleapis.com/css2?family=Cormorant+Garamond:wght@500;600;700&family=Inter:wght@400;500;600;700&display=swap" | D20: href="https://fonts.googleapis.com/css2?family=Cormorant+Garamond:wght@500;600;700&family=Inter:wght@400;500;600;700&display=swap" | E20: href="https://fonts.googleapis.com/css2?family=Cormorant+Garamond:wght@500;600;700&family=Inter:wght@400;500;600;700&display=swap" | F20: href="https://fonts.googleapis.com/css2?family=Cormorant+Garamond:wght@500;600;700&family=Inter:wght@400;500;600;700&display=swap" | G20: href="https://fonts.googleapis.com/css2?family=Cormorant+Garamond:wght@500;600;700&family=Inter:wght@400;500;600;700&display=swap" | H20: href="https://fonts.googleapis.com/css2?family=Cormorant+Garamond:wght@500;600;700&family=Inter:wght@400;500;600;700&display=swap" | I20: href="https://fonts.googleapis.com/css2?family=Cormorant+Garamond:wght@500;600;700&family=Inter:wght@400;500;600;700&display=swap" | J20: href="https://fonts.googleapis.com/css2?family=Cormorant+Garamond:wght@500;600;700&family=Inter:wght@400;500;600;700&display=swap" | K20: href="https://fonts.googleapis.com/css2?family=Cormorant+Garamond:wght@500;600;700&family=Inter:wght@400;500;600;700&display=swap" | L20: href="https://fonts.googleapis.com/css2?family=Cormorant+Garamond:wght@500;600;700&family=Inter:wght@400;500;600;700&display=swap" | M20: href="https://fonts.googleapis.com/css2?family=Cormorant+Garamond:wght@500;600;700&family=Inter:wght@400;500;600;700&display=swap" | N20: href="https://fonts.googleapis.com/css2?family=Cormorant+Garamond:wght@500;600;700&family=Inter:wght@400;500;600;700&display=swap" | O20: href="https://fonts.googleapis.com/css2?family=Cormorant+Garamond:wght@500;600;700&family=Inter:wght@400;500;600;700&display=swap" | P20: href="https://fonts.googleapis.com/css2?family=Cormorant+Garamond:wght@500;600;700&family=Inter:wght@400;500;600;700&display=swap" | Q20: href="https://fonts.googleapis.com/css2?family=Cormorant+Garamond:wght@500;600;700&family=Inter:wght@400;500;600;700&display=swap" | R20: href="https://fonts.googleapis.com/css2?family=Cormorant+Garamond:wght@500;600;700&family=Inter:wght@400;500;600;700&display=swap" | S20: href="https://fonts.googleapis.com/css2?family=Cormorant+Garamond:wght@500;600;700&family=Inter:wght@400;500;600;700&display=swap" | T20: href="https://fonts.googleapis.com/css2?family=Cormorant+Garamond:wght@500;600;700&family=Inter:wght@400;500;600;700&display=swap" | U20: href="https://fonts.googleapis.com/css2?family=Cormorant+Garamond:wght@500;600;700&family=Inter:wght@400;500;600;700&display=swap" | V20: href="https://fonts.googleapis.com/css2?family=Cormorant+Garamond:wght@500;600;700&family=Inter:wght@400;500;600;700&display=swap" | W20: href="https://fonts.googleapis.com/css2?family=Cormorant+Garamond:wght@500;600;700&family=Inter:wght@400;500;600;700&display=swap" | X20: href="https://fonts.googleapis.com/css2?family=Cormorant+Garamond:wght@500;600;700&family=Inter:wght@400;500;600;700&display=swap" | Y20: href="https://fonts.googleapis.com/css2?family=Cormorant+Garamond:wght@500;600;700&family=Inter:wght@400;500;600;700&display=swap" | Z20: href="https://fonts.googleapis.com/css2?family=Cormorant+Garamond:wght@500;600;700&family=Inter:wght@400;500;600;700&display=swap" | AA20: href="https://fonts.googleapis.com/css2?family=Cormorant+Garamond:wght@500;600;700&family=Inter:wght@400;500;600;700&display=swap" | AB20: href="https://fonts.googleapis.com/css2?family=Cormorant+Garamond:wght@500;600;700&family=Inter:wght@400;500;600;700&display=swap" | AC20: href="https://fonts.googleapis.com/css2?family=Cormorant+Garamond:wght@500;600;700&family=Inter:wght@400;500;600;700&display=swap" | AD20: href="https://fonts.googleapis.com/css2?family=Cormorant+Garamond:wght@500;600;700&family=Inter:wght@400;500;600;700&display=swap" | AE20: href="https://fonts.googleapis.com/css2?family=Cormorant+Garamond:wght@500;600;700&family=Inter:wght@400;500;600;700&display=swap" | AF20: href="https://fonts.googleapis.com/css2?family=Cormorant+Garamond:wght@500;600;700&family=Inter:wght@400;500;600;700&display=swap" | AG20: href="https://fonts.googleapis.com/css2?family=Cormorant+Garamond:wght@500;600;700&family=Inter:wght@400;500;600;700&display=swap"
B21: rel="stylesheet" | C21: rel="stylesheet" | D21: rel="stylesheet" | E21: rel="stylesheet" | F21: rel="stylesheet" | G21: rel="stylesheet" | H21: rel="stylesheet" | I21: rel="stylesheet" | J21: rel="stylesheet" | K21: rel="stylesheet"/> | L21: rel="stylesheet"/> | M21: rel="stylesheet"/> | N21: rel="stylesheet"/> | O21: rel="stylesheet"/> | P21: rel="stylesheet"/> | Q21: rel="stylesheet"/> | R21: rel="stylesheet"/> | S21: rel="stylesheet"/> | T21: rel="stylesheet"/> | U21: rel="stylesheet"/> | V21: rel="stylesheet"/> | W21: rel="stylesheet"/> | X21: rel="stylesheet"/> | Y21: rel="stylesheet"/> | Z21: rel="stylesheet"/> | AA21: rel="stylesheet"/> | AB21: rel="stylesheet"/> | AC21: rel="stylesheet"/> | AD21: rel="stylesheet"/> | AE21: rel="stylesheet"/> | AF21: rel="stylesheet"/> | AG21: rel="stylesheet"/>
B22: /> | C22: /> | D22: /> | E22: /> | F22: /> | G22: /> | H22: /> | I22: /> | J22: /> | K22: <link rel="stylesheet" href="https://fonts.googleapis.com/css2?family=Material+Symbols+Outlined:opsz,wght,FILL,GRAD@20..48,100..700,0..1,-50..200&icon_names=dictionary,folded_hands,movie_speaker,today,home,settings,settings_accessibility" /> | L22: <link rel="stylesheet" href="https://fonts.googleapis.com/css2?family=Material+Symbols+Outlined:opsz,wght,FILL,GRAD@20..48,100..700,0..1,-50..200&icon_names=dictionary,folded_hands,movie_speaker,today,home,settings,settings_accessibility" /> | M22: <link rel="stylesheet" href="https://fonts.googleapis.com/css2?family=Material+Symbols+Outlined:opsz,wght,FILL,GRAD@20..48,100..700,0..1,-50..200&icon_names=dictionary,folded_hands,movie_speaker,today,home,settings,settings_accessibility" /> | N22: <link rel="stylesheet" href="https://fonts.googleapis.com/css2?family=Material+Symbols+Outlined:opsz,wght,FILL,GRAD@20..48,100..700,0..1,-50..200&icon_names=dictionary,folded_hands,movie_speaker,today,home,settings,settings_accessibility" /> | O22: <link rel="stylesheet" href="https://fonts.googleapis.com/css2?family=Material+Symbols+Outlined:opsz,wght,FILL,GRAD@20..48,100..700,0..1,-50..200&icon_names=dictionary,folded_hands,movie_speaker,today,home,settings,settings_accessibility" /> | P22: <link rel="stylesheet" href="https://fonts.googleapis.com/css2?family=Material+Symbols+Outlined:opsz,wght,FILL,GRAD@20..48,100..700,0..1,-50..200&icon_names=dictionary,folded_hands,movie_speaker,today,home,settings,settings_accessibility" /> | Q22: <link rel="stylesheet" href="https://fonts.googleapis.com/css2?family=Material+Symbols+Outlined:opsz,wght,FILL,GRAD@20..48,100..700,0..1,-50..200&icon_names=dictionary,folded_hands,movie_speaker,today,home,settings,settings_accessibility" /> | R22: <link rel="stylesheet" href="https://fonts.googleapis.com/css2?family=Material+Symbols+Outlined:opsz,wght,FILL,GRAD@20..48,100..700,0..1,-50..200&icon_names=dictionary,folded_hands,movie_speaker,today,home,settings,settings_accessibility" /> | S22: <link rel="stylesheet" href="https://fonts.googleapis.com/css2?family=Material+Symbols+Outlined:opsz,wght,FILL,GRAD@20..48,100..700,0..1,-50..200&icon_names=dictionary,folded_hands,movie_speaker,today,home,settings,settings_accessibility" /> | T22: <link rel="stylesheet" href="https://fonts.googleapis.com/css2?family=Material+Symbols+Outlined:opsz,wght,FILL,GRAD@20..48,100..700,0..1,-50..200&icon_names=dictionary,folded_hands,movie_speaker,today,home,settings,settings_accessibility" /> | U22: <link rel="stylesheet" href="https://fonts.googleapis.com/css2?family=Material+Symbols+Outlined:opsz,wght,FILL,GRAD@20..48,100..700,0..1,-50..200&icon_names=dictionary,folded_hands,movie_speaker,today,home,settings,settings_accessibility" /> | V22: <link rel="stylesheet" href="https://fonts.googleapis.com/css2?family=Material+Symbols+Outlined:opsz,wght,FILL,GRAD@20..48,100..700,0..1,-50..200&icon_names=dictionary,folded_hands,movie_speaker,today,home,settings,settings_accessibility" /> | W22: <link rel="stylesheet" href="https://fonts.googleapis.com/css2?family=Material+Symbols+Outlined:opsz,wght,FILL,GRAD@20..48,100..700,0..1,-50..200&icon_names=dictionary,folded_hands,movie_speaker,today,home,settings,settings_accessibility" /> | X22: <link rel="stylesheet" href="https://fonts.googleapis.com/css2?family=Material+Symbols+Outlined:opsz,wght,FILL,GRAD@20..48,100..700,0..1,-50..200&icon_names=dictionary,folded_hands,movie_speaker,today,home,settings,settings_accessibility" /> | Y22: <link rel="stylesheet" href="https://fonts.googleapis.com/css2?family=Material+Symbols+Outlined:opsz,wght,FILL,GRAD@20..48,100..700,0..1,-50..200&icon_names=dictionary,folded_hands,movie_speaker,today,home,settings,settings_accessibility" /> | Z22: <link rel="stylesheet" href="https://fonts.googleapis.com/css2?family=Material+Symbols+Outlined:opsz,wght,FILL,GRAD@20..48,100..700,0..1,-50..200&icon_names=dictionary,folded_hands,movie_speaker,today,home,settings,settings_accessibility" /> | AA22: <link rel="stylesheet" href="https://fonts.googleapis.com/css2?family=Material+Symbols+Outlined:opsz,wght,FILL,GRAD@20..48,100..700,0..1,-50..200&icon_names=dictionary,folded_hands,movie_speaker,today,home,settings,settings_accessibility" /> | AB22: <link rel="stylesheet" href="https://fonts.googleapis.com/css2?family=Material+Symbols+Outlined:opsz,wght,FILL,GRAD@20..48,100..700,0..1,-50..200&icon_names=dictionary,folded_hands,movie_speaker,today,home,settings,settings_accessibility" /> | AC22: <link rel="stylesheet" href="https://fonts.googleapis.com/css2?family=Material+Symbols+Outlined:opsz,wght,FILL,GRAD@20..48,100..700,0..1,-50..200&icon_names=dictionary,folded_hands,movie_speaker,today,home,settings,settings_accessibility" /> | AD22: <link rel="stylesheet" href="https://fonts.googleapis.com/css2?family=Material+Symbols+Outlined:opsz,wght,FILL,GRAD@20..48,100..700,0..1,-50..200&icon_names=dictionary,folded_hands,movie_speaker,today,home,settings,settings_accessibility" /> | AE22: <link rel="stylesheet" href="https://fonts.googleapis.com/css2?family=Material+Symbols+Outlined:opsz,wght,FILL,GRAD@20..48,100..700,0..1,-50..200&icon_names=dictionary,folded_hands,movie_speaker,today,home,settings,settings_accessibility" /> | AF22: <link rel="stylesheet" href="https://fonts.googleapis.com/css2?family=Material+Symbols+Outlined:opsz,wght,FILL,GRAD@20..48,100..700,0..1,-50..200&icon_names=dictionary,folded_hands,movie_speaker,today,home,settings,settings_accessibility" /> | AG22: <link rel="stylesheet" href="https://fonts.googleapis.com/css2?family=Material+Symbols+Outlined:opsz,wght,FILL,GRAD@20..48,100..700,0..1,-50..200&icon_names=dictionary,folded_hands,movie_speaker,today,home,settings,settings_accessibility" />
B23: <link rel="stylesheet" href="../style.css" /> | C23: <link rel="stylesheet" href="../style.css" /> | D23: <link rel="stylesheet" href="../style.css" /> | E23: <link rel="stylesheet" href="../style.css" /> | F23: <link rel="stylesheet" href="../style.css" /> | G23: <link rel="stylesheet" href="../style.css" /> | H23: <link rel="stylesheet" href="../style.css" /> | I23: <link rel="stylesheet" href="../style.css" /> | J23: <link rel="stylesheet" href="../style.css" /> | K23: <link rel="stylesheet" href="../style.css" /> | L23: <link rel="stylesheet" href="../style.css" /> | M23: <link rel="stylesheet" href="../style.css" /> | N23: <link rel="stylesheet" href="../style.css" /> | O23: <link rel="stylesheet" href="../style.css" /> | P23: <link rel="stylesheet" href="../style.css" /> | Q23: <link rel="stylesheet" href="../style.css" /> | R23: <link rel="stylesheet" href="../style.css" /> | S23: <link rel="stylesheet" href="../style.css" /> | T23: <link rel="stylesheet" href="../style.css" /> | U23: <link rel="stylesheet" href="../style.css" /> | V23: <link rel="stylesheet" href="../style.css" /> | W23: <link rel="stylesheet" href="../style.css" /> | X23: <link rel="stylesheet" href="../style.css" /> | Y23: <link rel="stylesheet" href="../style.css" /> | Z23: <link rel="stylesheet" href="../style.css" /> | AA23: <link rel="stylesheet" href="../style.css" /> | AB23: <link rel="stylesheet" href="../style.css" /> | AC23: <link rel="stylesheet" href="../style.css" /> | AD23: <link rel="stylesheet" href="../style.css" /> | AE23: <link rel="stylesheet" href="../style.css" /> | AF23: <link rel="stylesheet" href="../style.css" /> | AG23: <link rel="stylesheet" href="../style.css" />
B24: </head> | C24: </head> | D24: </head> | E24: </head> | F24: </head> | G24: </head> | H24: </head> | I24: </head> | J24: </head> | K24: </head> | L24: </head> | M24: </head> | N24: </head> | O24: </head> | P24: </head> | Q24: </head> | R24: </head> | S24: </head> | T24: </head> | U24: </head> | V24: </head> | W24: </head> | X24: </head> | Y24: </head> | Z24: </head> | AA24: </head> | AB24: </head> | AC24: </head> | AD24: </head> | AE24: </head> | AF24: </head> | AG24: </head>
B25: <body> | C25: <body> | D25: <body> | E25: <body> | F25: <body> | G25: <body> | H25: <body> | I25: <body> | J25: <body> | K25: <body> | L25: <body> | M25: <body> | N25: <body> | O25: <body> | P25: <body> | Q25: <body> | R25: <body> | S25: <body> | T25: <body> | U25: <body> | V25: <body> | W25: <body> | X25: <body> | Y25: <body> | Z25: <body> | AA25: <body> | AB25: <body> | AC25: <body> | AD25: <body> | AE25: <body> | AF25: <body> | AG25: <body>
B26: <a class="skip-link" href="#main">Zum Inhalt springen</a> | C26: <a class="skip-link" href="#main">Zum Inhalt springen</a> | D26: <a class="skip-link" href="#main">Zum Inhalt springen</a> | E26: <a class="skip-link" href="#main">Zum Inhalt springen</a> | F26: <a class="skip-link" href="#main">Zum Inhalt springen</a> | G26: <a class="skip-link" href="#main">Zum Inhalt springen</a> | H26: <a class="skip-link" href="#main">Zum Inhalt springen</a> | I26: <a class="skip-link" href="#main">Zum Inhalt springen</a> | J26: <a class="skip-link" href="#main">Zum Inhalt springen</a> | K26: <a class="skip-link" href="#main">Zum Inhalt springen</a> | L26: <a class="skip-link" href="#main">Zum Inhalt springen</a> | M26: <a class="skip-link" href="#main">Zum Inhalt springen</a> | N26: <a class="skip-link" href="#main">Zum Inhalt springen</a> | O26: <a class="skip-link" href="#main">Zum Inhalt springen</a> | P26: <a class="skip-link" href="#main">Zum Inhalt springen</a> | Q26: <a class="skip-link" href="#main">Zum Inhalt springen</a> | R26: <a class="skip-link" href="#main">Zum Inhalt springen</a> | S26: <a class="skip-link" href="#main">Zum Inhalt springen</a> | T26: <a class="skip-link" href="#main">Zum Inhalt springen</a> | U26: <a class="skip-link" href="#main">Zum Inhalt springen</a> | V26: <a class="skip-link" href="#main">Zum Inhalt springen</a> | W26: <a class="skip-link" href="#main">Zum Inhalt springen</a> | X26: <a class="skip-link" href="#main">Zum Inhalt springen</a> | Y26: <a class="skip-link" href="#main">Zum Inhalt springen</a> | Z26: <a class="skip-link" href="#main">Zum Inhalt springen</a> | AA26: <a class="skip-link" href="#main">Zum Inhalt springen</a> | AB26: <a class="skip-link" href="#main">Zum Inhalt springen</a> | AC26: <a class="skip-link" href="#main">Zum Inhalt springen</a> | AD26: <a class="skip-link" href="#main">Zum Inhalt springen</a> | AE26: <a class="skip-link" href="#main">Zum Inhalt springen</a> | AF26: <a class="skip-link" href="#main">Zum Inhalt springen</a> | AG26: <a class="skip-link" href="#main">Zum Inhalt springen</a>
